Workbook

Sheet الهيكل
A1: المستوى | B1: الصفحة | C1: تتبع | D1: الرابط المقترح | E1: الكلمة الرئيسية | F1: SV الرئيسية | G1: عدد الكلمات | H1: مجموع SV | I1: نية البحث
A2: المظلة | B2: الهب: شركة تصميم مواقع الويب | C2: — | D2: /web-design/ | E2: شركة تصميم مواقع الويب (H1) + شركة تصميم مواقع (Title) | F2: 2400 | G2: =COUNTIF(التوزيع!$D$2:$D$182,B2) -> 28 | H2: =SUMIF(التوزيع!$D$2:$D$182,B2,التوزيع!$B$2:$B$182) -> 12880 | I2: تجارية: يبحث عن شركة أو عن الخدمة عموماً
A3: Pillar 1 | B3: موقع مخصص | C3: الهب | D3: /web-design/custom-website/ | E3: تصميم موقع إلكتروني | F3: 1600 | G3: =COUNTIF(التوزيع!$D$2:$D$182,B3) -> 26 | H3: =SUMIF(التوزيع!$D$2:$D$182,B3,التوزيع!$B$2:$B$182) -> 3670 | I3: شرائية: يريد من ينفذ له موقعاً
A4: Cluster | B4: مقال: تكلفة إنشاء موقع إلكتروني في مصر 2026: دليل الأسعار | C4: Pillar 1 | D4: /blog/[تأكيد] | E4: تكلفة انشاء موقع الكتروني | F4: 140 | G4: =COUNTIF(التوزيع!$D$2:$D$182,B4) -> 12 | H4: =SUMIF(التوزيع!$D$2:$D$182,B4,التوزيع!$B$2:$B$182) -> 680 | I4: بحث قبل الشراء: يقارن التكلفة
A5: Cluster | B5: مقال: أنواع المواقع الإلكترونية | C5: Pillar 1 | D5: /blog/[تأكيد] | E5: انواع المواقع الالكترونية | F5: 30 | G5: =COUNTIF(التوزيع!$D$2:$D$182,B5) -> 14 | H5: =SUMIF(التوزيع!$D$2:$D$182,B5,التوزيع!$B$2:$B$182) -> 19420 | I5: معلوماتية
A6: Cluster | B6: مقال: كيف تنشئ موقعاً إلكترونياً لنشاطك: بنفسك أم مع شركة؟ | C6: Pillar 1 | D6: /blog/[تأكيد] | E6: انشاء موقع الكتروني | F6: 2400 | G6: =COUNTIF(التوزيع!$D$2:$D$182,B6) -> 20 | H6: =SUMIF(التوزيع!$D$2:$D$182,B6,التوزيع!$B$2:$B$182) -> 9300 | I6: معلوماتية: يتعلم الخطوات
A7: Pillar 2 | B7: موقع تديره بنفسك (ووردبريس) | C7: الهب | D7: /web-design/wordpress/ | E7: تصميم مواقع ووردبريس | F7: 140 | G7: =COUNTIF(التوزيع!$D$2:$D$182,B7) -> 12 | H7: =SUMIF(التوزيع!$D$2:$D$182,B7,التوزيع!$B$2:$B$182) -> 990 | I7: شرائية
A8: Cluster | B8: مقال: ما هو ووردبريس، وهل يناسب موقع شركتك؟ | C8: Pillar 2 | D8: /blog/[تأكيد] | E8: موقع wordpress | F8: 50 | G8: =COUNTIF(التوزيع!$D$2:$D$182,B8) -> 4 | H8: =SUMIF(التوزيع!$D$2:$D$182,B8,التوزيع!$B$2:$B$182) -> 230 | I8: معلوماتية
A9: Pillar 3 | B9: المتجر الإلكتروني المخصص | C9: الهب | D9: /web-design/online-store/ | E9: تصميم متجر الكتروني | F9: 210 | G9: =COUNTIF(التوزيع!$D$2:$D$182,B9) -> 22 | H9: =SUMIF(التوزيع!$D$2:$D$182,B9,التوزيع!$B$2:$B$182) -> 4290 | I9: شرائية
A10: Cluster | B10: مقال: تكلفة إنشاء متجر إلكتروني في مصر | C10: Pillar 3 | D10: /blog/[تأكيد] | E10: تكلفة عمل متجر الكتروني | F10: 260 | G10: =COUNTIF(التوزيع!$D$2:$D$182,B10) -> 4 | H10: =SUMIF(التوزيع!$D$2:$D$182,B10,التوزيع!$B$2:$B$182) -> 570 | I10: بحث قبل الشراء: يقارن التكلفة
A11: Cluster | B11: مقال: كيف تنشئ متجراً إلكترونياً: منصة جاهزة أم متجر مخصص؟ | C11: Pillar 3 | D11: /blog/[تأكيد] | E11: إنشاء متجر إلكتروني | F11: 1900 | G11: =COUNTIF(التوزيع!$D$2:$D$182,B11) -> 6 | H11: =SUMIF(التوزيع!$D$2:$D$182,B11,التوزيع!$B$2:$B$182) -> 2440 | I11: معلوماتية
A12: Cluster | B12: مقال: ابدأ التجارة الإلكترونية في مصر | C12: Pillar 3 | D12: /blog/[تأكيد] | E12: التجارة الإلكترونية | F12: 1600 | G12: =COUNTIF(التوزيع!$D$2:$D$182,B12) -> 1 | H12: =SUMIF(التوزيع!$D$2:$D$182,B12,التوزيع!$B$2:$B$182) -> 1600 | I12: معلوماتية
A13: Cluster | B13: مقال: أفضل موقع لإنشاء متجر إلكتروني | C13: Pillar 3 | D13: /blog/[تأكيد] | E13: أفضل موقع لإنشاء متجر الكتروني | F13: 170 | G13: =COUNTIF(التوزيع!$D$2:$D$182,B13) -> 2 | H13: =SUMIF(التوزيع!$D$2:$D$182,B13,التوزيع!$B$2:$B$182) -> 190 | I13: معلوماتية: يقارن المنصات
A14: Pillar 4 | B14: متجر سلة | C14: الهب | D14: /web-design/salla-store/ | E14: تصميم متجر سلة | F14: 70 | G14: =COUNTIF(التوزيع!$D$2:$D$182,B14) -> 2 | H14: =SUMIF(التوزيع!$D$2:$D$182,B14,التوزيع!$B$2:$B$182) -> 140 | I14: شرائية
A15: الرئيسية | B15: الصفحة الرئيسية (قسم المواقع) | C15: — | D15: / | E15: — | G15: =COUNTIF(التوزيع!$D$2:$D$182,B15) -> 4 | H15: =SUMIF(التوزيع!$D$2:$D$182,B15,التوزيع!$B$2:$B$182) -> 8290 | I15: علامة تجارية
A16: غير مستهدف | B16: غير مستهدف (نية تعلم أو وظائف) | C16: — | D16: — | E16: — | G16: =COUNTIF(التوزيع!$D$2:$D$182,B16) -> 7 | H16: =SUMIF(التوزيع!$D$2:$D$182,B16,التوزيع!$B$2:$B$182) -> 5600 | I16: تعلم
A17: مستبعد | B17: مستبعد | C17: — | D17: — | E17: — | G17: =COUNTIF(التوزيع!$D$2:$D$182,B17) -> 17 | H17: =SUMIF(التوزيع!$D$2:$D$182,B17,التوزيع!$B$2:$B$182) -> 3310 | I17: خارج النطاق
B18: الإجمالي | G18: =SUM(G2:G17) -> 181 | H18: =SUM(H2:H17) -> 73600
B19: تحقق: عدد الكلمات | G19: =COUNTA(التوزيع!$A$2:$A$182) -> 181
A21: مراجعة 7 أكتوبر 2026: رُوجعت نية البحث لكل الكلمات الـ 181 ببحث فعلي، كلمة كلمة لكل صيغة رئيسية، والصيغ الإملائية تأخذ نية الكلمة التي تشبهها.
A22: حدود المراجعة: أداة البحث المستخدمة تعرض نتائج عربية لكنها ليست مضبوطة على جوجل مصر، فهي تحدد النية لا الترتيب. الكلمات المكتوب أمامها «تحتاج تأكيداً» تُراجع يدوياً من مصر.
A23: الخلية الصفراء في عمود «تغيّر بعد التحقق» تعني أن الكلمة انتقلت من صفحتها السابقة.
A24: أُلغي مقال «إنشاء متجر سلة خطوة بخطوة» لأن نتائج كلمته عروض خدمات، فانتقلت لصفحة سلة. وأُضيف مقال «تكلفة إنشاء متجر إلكتروني في مصر».

Sheet التوزيع
A1: الكلمة | B1: SV | C1: المستوى | D1: الصفحة | E1: تتبع | F1: نية البحث | G1: الدور | H1: الموضع في الصفحة | I1: ماذا ظهر في نتائج البحث | J1: تغيّر بعد التحقق
A2: شركة تصميم مواقع | B2: 2400 | C2: المظلة | D2: الهب: شركة تصميم مواقع الويب | E2: — | F2: تجارية: يبحث عن شركة أو عن الخدمة عموماً | G2: رئيسية | H2: Title + ضمن H1 + Meta + أول جملة في «أي خدمة تحتاج؟» | I2: تحققك من مصر: خريطة شركات محلية (Local Pack) في القاهرة + قوائم «أفضل شركات تصميم مواقع»: تجارية محلية مؤكدة | J2: نعم (تأكيد)
A3: شركة تصميم مواقع الويب | B3: 2400 | C3: المظلة | D3: الهب: شركة تصميم مواقع الويب | E3: — | F3: تجارية: يبحث عن شركة أو عن الخدمة عموماً | G3: رئيسية | H3: H1 (مطابق حرفياً) + Meta | I3: صيغة «شركة» تجارية بطبيعتها؛ أداة البحث أعادت نتائج ضعيفة، يُفضّل تأكيدها من مصر
A4: شركات تصميم مواقع | B4: 2400 | C4: المظلة | D4: الهب: شركة تصميم مواقع الويب | E4: — | F4: تجارية: يبحث عن شركة أو عن الخدمة عموماً | G4: رئيسية (صيغة الجمع) | H4: مقدمة «لماذا كاتكس» | I4: صيغة «شركة» تجارية بطبيعتها؛ أداة البحث أعادت نتائج ضعيفة، يُفضّل تأكيدها من مصر
A5: تصميم مواقع | B5: 1300 | C5: المظلة | D5: الهب: شركة تصميم مواقع الويب | E5: — | F5: تجارية: يبحث عن شركة أو عن الخدمة عموماً | G5: داعمة | H5: H2 قسم الخدمات | I5: تحققك من مصر: أغلب النتائج شركات | J5: نعم
A6: تصميم مواقع / تصميم المواقع | B6: 720 | C6: المظلة | D6: الهب: شركة تصميم مواقع الويب | E6: — | F6: تجارية: يبحث عن شركة أو عن الخدمة عموماً | G6: داعمة | H6: العنوان الصغير «خدمات تصميم المواقع» | I6: خليط: عروض خدمات ومنتديات وأدلة، يميل للتجاري | J6: نعم
A7: شركات تصميم المواقع في مصر | B7: 390 | C7: المظلة | D7: الهب: شركة تصميم مواقع الويب | E7: — | F7: تجارية: يبحث عن شركة أو عن الخدمة عموماً | G7: داعمة | H7: فقرة المقر في «لماذا كاتكس» | I7: أدلة شركات (الصفحات الصفراء) ووظائف: تجارية محلية
A8: شركة تصميم مواقع في مصر | B8: 390 | C8: المظلة | D8: الهب: شركة تصميم مواقع الويب | E8: — | F8: تجارية: يبحث عن شركة أو عن الخدمة عموماً | G8: داعمة | H8: Title + أول جملة في «أي خدمة تحتاج؟» + Schema | I8: أدلة شركات (الصفحات الصفراء) ووظائف: تجارية محلية
A9: تصميم المواقع الإلكترونية / تصميم مواقع الكترونيه | B9: 390 | C9: المظلة | D9: الهب: شركة تصميم مواقع الويب | E9: — | F9: تجارية: يبحث عن شركة أو عن الخدمة عموماً | G9: داعمة | H9: مقدمة قسم الخدمات | I9: خليط: عروض خدمات وأداة بناء وأدلة | J9: نعم
A10: أفضل شركة تصميم مواقع في مصر | B10: 320 | C10: المظلة | D10: الهب: شركة تصميم مواقع الويب | E10: — | F10: تجارية: يبحث عن شركة أو عن الخدمة عموماً | G10: داعمة | H10: H2 «لماذا كاتكس» | I10: صيغة إملائية/مرادفة لكلمة مُتحقق منها في نفس الصفحة
A11: شركة تصميم مواقع الكترونية | B11: 320 | C11: المظلة | D11: الهب: شركة تصميم مواقع الويب | E11: — | F11: تجارية: يبحث عن شركة أو عن الخدمة عموماً | G11: داعمة | H11: مقدمة «لماذا كاتكس» (داخل «أفضل شركة تصميم مواقع إلكترونية») | I11: صيغة إملائية/مرادفة لكلمة مُتحقق منها في نفس الصفحة
A12: تطوير مواقع / تطوير المواقع | B12: 110 | C12: المظلة | D12: الهب: شركة تصميم مواقع الويب | E12: — | F12: تجارية: يبحث عن شركة أو عن الخدمة عموماً | G12: داعمة | H12: مقدمة قسم الخدمات («وتطوير مواقع الويب») | I12: عروض خدمات على خمسات ومستقل (يريد من ينفذ) | J12: نعم
A13: شركات تصميم مواقع في القاهرة | B13: 90 | C13: المظلة | D13: الهب: شركة تصميم مواقع الويب | E13: — | F13: تجارية: يبحث عن شركة أو عن الخدمة عموماً | G13: داعمة | H13: فقرة المقر في «لماذا كاتكس» | I13: صيغة إملائية/مرادفة لكلمة مُتحقق منها في نفس الصفحة
A14: تصميم مواقع الكترونية في مصر | B14: 70 | C14: المظلة | D14: الهب: شركة تصميم مواقع الويب | E14: — | F14: تجارية: يبحث عن شركة أو عن الخدمة عموماً | G14: داعمة | H14: فقرة المقر في «لماذا كاتكس» | I14: صيغة إملائية/مرادفة لكلمة مُتحقق منها في نفس الصفحة
A15: شركة انشاء مواقع الكترونية | B15: 40 | C15: المظلة | D15: الهب: شركة تصميم مواقع الويب | E15: — | F15: تجارية: يبحث عن شركة أو عن الخدمة عموماً | G15: داعمة | H15: فقرة المقر في «لماذا كاتكس» | I15: صيغة إملائية/مرادفة لكلمة مُتحقق منها في نفس الصفحة
A16: أفضل شركة تصميم مواقع الكترونية | B16: 30 | C16: المظلة | D16: الهب: شركة تصميم مواقع الويب | E16: — | F16: تجارية: يبحث عن شركة أو عن الخدمة عموماً | G16: داعمة | H16: مقدمة «لماذا كاتكس» | I16: صيغة إملائية/مرادفة لكلمة مُتحقق منها في نفس الصفحة
A17: تطوير مواقع الويب | B17: 30 | C17: المظلة | D17: الهب: شركة تصميم مواقع الويب | E17: — | F17: تجارية: يبحث عن شركة أو عن الخدمة عموماً | G17: داعمة | H17: مقدمة قسم الخدمات | I17: عروض خدمات على خمسات ومستقل (يريد من ينفذ) وصفحة شركة | J17: نعم
A18: خدمات تصميم المواقع | B18: 20 | C18: المظلة | D18: الهب: شركة تصميم مواقع الويب | E18: — | F18: تجارية: يبحث عن شركة أو عن الخدمة عموماً | G18: داعمة | H18: العنوان الصغير فوق «أي خدمة تحتاج؟» | I18: صيغة إملائية/مرادفة لكلمة مُتحقق منها في نفس الصفحة
A19: أفضل شركة تصميم مواقع فى مصر | B19: 320 | C19: المظلة | D19: الهب: شركة تصميم مواقع الويب | E19: — | F19: تجارية: يبحث عن شركة أو عن الخدمة عموماً | G19: متغير | H19: — | I19: صيغة إملائية/مرادفة لكلمة مُتحقق منها في نفس الصفحة
A20: تصميم مواقع الكترونية | B20: 320 | C20: المظلة | D20: الهب: شركة تصميم مواقع الويب | E20: — | F20: تجارية: يبحث عن شركة أو عن الخدمة عموماً | G20: متغير | H20: — | I20: عروض خدمات على خمسات ومستقل (يريد من ينفذ) | J20: نعم
A21: أفضل شركة تصميم مواقع / افضل شركة تصميم المواقع / افضل شركة لتصميم المواقع | B21: 260 | C21: المظلة | D21: الهب: شركة تصميم مواقع الويب | E21: — | F21: تجارية: يبحث عن شركة أو عن الخدمة عموماً | G21: متغير | H21: داخل H2 «لماذا كاتكس» | I21: صيغة إملائية/مرادفة لكلمة مُتحقق منها في نفس الصفحة
A22: شركات تصميم مواقع فى مصر | B22: 260 | C22: المظلة | D22: الهب: شركة تصميم مواقع الويب | E22: — | F22: تجارية: يبحث عن شركة أو عن الخدمة عموماً | G22: متغير | H22: — | I22: صيغة إملائية/مرادفة لكلمة مُتحقق منها في نفس الصفحة
A23: شركات تصميم مواقع الكترونية في مصر | B23: 90 | C23: المظلة | D23: الهب: شركة تصميم مواقع الويب | E23: — | F23: تجارية: يبحث عن شركة أو عن الخدمة عموماً | G23: متغير | H23: — | I23: صيغة إملائية/مرادفة لكلمة مُتحقق منها في نفس الصفحة
A24: شركة تصميم مواقع الكترونية في مصر | B24: 90 | C24: المظلة | D24: الهب: شركة تصميم مواقع الويب | E24: — | F24: تجارية: يبحث عن شركة أو عن الخدمة عموماً | G24: متغير | H24: — | I24: صيغة إملائية/مرادفة لكلمة مُتحقق منها في نفس الصفحة
A25: شركات انشاء مواقع الكترونية | B25: 40 | C25: المظلة | D25: الهب: شركة تصميم مواقع الويب | E25: — | F25: تجارية: يبحث عن شركة أو عن الخدمة عموماً | G25: متغير | H25: — | I25: صيغة إملائية/مرادفة لكلمة مُتحقق منها في نفس الصفحة
A26: أفضل شركة تصميم مواقع إلكترونية | B26: 20 | C26: المظلة | D26: الهب: شركة تصميم مواقع الويب | E26: — | F26: تجارية: يبحث عن شركة أو عن الخدمة عموماً | G26: متغير | H26: — | I26: صيغة إملائية/مرادفة لكلمة مُتحقق منها في نفس الصفحة
A27: شركات تصميم مواقع الكترونية / شركات تصميم المواقع الالكترونية | B27: 20 | C27: المظلة | D27: الهب: شركة تصميم مواقع الويب | E27: — | F27: تجارية: يبحث عن شركة أو عن الخدمة عموماً | G27: متغير | H27: — | I27: صيغة إملائية/مرادفة لكلمة مُتحقق منها في نفس الصفحة
A28: شركة تصميم ويب سايت | B28: 20 | C28: المظلة | D28: الهب: شركة تصميم مواقع الويب | E28: — | F28: تجارية: يبحث عن شركة أو عن الخدمة عموماً | G28: متغير | H28: — | I28: صيغة إملائية/مرادفة لكلمة مُتحقق منها في نفس الصفحة
A29: تصميم مواقع احترافية | B29: 20 | C29: المظلة | D29: الهب: شركة تصميم مواقع الويب | E29: — | F29: تجارية: يبحث عن شركة أو عن الخدمة عموماً | G29: متغير | H29: — | I29: عروض خدمات على خمسات ومستقل (يريد من ينفذ) | J29: نعم
A30: تصميم موقع إلكتروني | B30: 1600 | C30: Pillar 1 | D30: موقع مخصص | E30: الهب | F30: شرائية: يريد من ينفذ له موقعاً | G30: رئيسية | H30: Title + H1 + أول جملة | I30: عروض خدمات على خمسات ومستقل (يريد من ينفذ)
A31: شركة برمجة مواقع | B31: 140 | C31: Pillar 1 | D31: موقع مخصص | E31: الهب | F31: شرائية: يريد من ينفذ له موقعاً | G31: داعمة | H31: H2 الموقع بنظام خاص | I31: عروض خدمات على خمسات ومستقل (يريد من ينفذ)
A32: تصميم ويب سايت | B32: 90 | C32: Pillar 1 | D32: موقع مخصص | E32: الهب | F32: شرائية: يريد من ينفذ له موقعاً | G32: داعمة | H32: نص المقدمة | I32: عروض خدمات على خمسات ومستقل (يريد من ينفذ)
A33: سعر تصميم موقع الكتروني | B33: 90 | C33: Pillar 1 | D33: موقع مخصص | E33: الهب | F33: شرائية: يريد من ينفذ له موقعاً | G33: داعمة | H33: Meta + بطاقة السعر | I33: عروض خدمات على خمسات ومستقل (يريد من ينفذ)
A34: شركة برمجة وتصميم مواقع | B34: 70 | C34: Pillar 1 | D34: موقع مخصص | E34: الهب | F34: شرائية: يريد من ينفذ له موقعاً | G34: داعمة | H34: نص الموقع بنظام خاص | I34: صيغة إملائية/مرادفة لكلمة مُتحقق منها في نفس الصفحة
A35: تصميم صفحات الويب | B35: 50 | C35: Pillar 1 | D35: موقع مخصص | E35: الهب | F35: شرائية: يريد من ينفذ له موقعاً | G35: داعمة | H35: نص قسم «ما يشمله» | I35: عروض خدمات على خمسات ومستقل (يريد من ينفذ)
A36: تصميم مواقع شركات | B36: 50 | C36: Pillar 1 | D36: موقع مخصص | E36: الهب | F36: شرائية: يريد من ينفذ له موقعاً | G36: داعمة | H36: نص الموقع الثابت | I36: خليط: مقالات عن تصميم مواقع الشركات وعروض خدمات
A37: شركة تصميم موقع الكتروني | B37: 50 | C37: Pillar 1 | D37: موقع مخصص | E37: الهب | F37: شرائية: يريد من ينفذ له موقعاً | G37: داعمة | H37: نص «لماذا كاتكس» في الخدمة 1 | I37: صيغة إملائية/مرادفة لكلمة مُتحقق منها في نفس الصفحة
A38: عرض سعر تصميم موقع الكتروني | B38: 50 | C38: Pillar 1 | D38: موقع مخصص | E38: الهب | F38: شرائية: يريد من ينفذ له موقعاً | G38: داعمة | H38: زر «اطلب عرض سعر» | I38: خليط: عروض خدمات ودليل لكتابة عرض سعر
A39: تصميم صفحة هبوط | B39: 40 | C39: Pillar 1 | D39: موقع مخصص | E39: الهب | F39: شرائية: يريد من ينفذ له موقعاً | G39: داعمة | H39: H3 صفحات الهبوط | I39: عروض خدمات على خمسات ومستقل (يريد من ينفذ)
A40: تصميم موقع إلكتروني احترافي | B40: 40 | C40: Pillar 1 | D40: موقع مخصص | E40: الهب | F40: شرائية: يريد من ينفذ له موقعاً | G40: داعمة | H40: Meta | I40: صيغة إملائية/مرادفة لكلمة مُتحقق منها في نفس الصفحة
...

Sheet الهب
A1: الصفحة | B1: المستوى | C1: الكلمة | D1: SV | E1: الدور | F1: الموضع في الصفحة | G1: تغيّر
A2: الهب: شركة تصميم مواقع الويب | B2: المظلة | C2: شركة تصميم مواقع | D2: 2400 | E2: رئيسية | F2: Title + ضمن H1 + Meta + أول جملة في «أي خدمة تحتاج؟» | G2: نعم (تأكيد)
A3: الهب: شركة تصميم مواقع الويب | B3: المظلة | C3: شركة تصميم مواقع الويب | D3: 2400 | E3: رئيسية | F3: H1 (مطابق حرفياً) + Meta
A4: الهب: شركة تصميم مواقع الويب | B4: المظلة | C4: شركات تصميم مواقع | D4: 2400 | E4: رئيسية (صيغة الجمع) | F4: مقدمة «لماذا كاتكس»
A5: الهب: شركة تصميم مواقع الويب | B5: المظلة | C5: تصميم مواقع | D5: 1300 | E5: داعمة | F5: H2 قسم الخدمات | G5: نعم
A6: الهب: شركة تصميم مواقع الويب | B6: المظلة | C6: تصميم مواقع / تصميم المواقع | D6: 720 | E6: داعمة | F6: العنوان الصغير «خدمات تصميم المواقع» | G6: نعم
A7: الهب: شركة تصميم مواقع الويب | B7: المظلة | C7: شركات تصميم المواقع في مصر | D7: 390 | E7: داعمة | F7: فقرة المقر في «لماذا كاتكس»
A8: الهب: شركة تصميم مواقع الويب | B8: المظلة | C8: شركة تصميم مواقع في مصر | D8: 390 | E8: داعمة | F8: Title + أول جملة في «أي خدمة تحتاج؟» + Schema
A9: الهب: شركة تصميم مواقع الويب | B9: المظلة | C9: تصميم المواقع الإلكترونية / تصميم مواقع الكترونيه | D9: 390 | E9: داعمة | F9: مقدمة قسم الخدمات | G9: نعم
A10: الهب: شركة تصميم مواقع الويب | B10: المظلة | C10: أفضل شركة تصميم مواقع في مصر | D10: 320 | E10: داعمة | F10: H2 «لماذا كاتكس»
A11: الهب: شركة تصميم مواقع الويب | B11: المظلة | C11: شركة تصميم مواقع الكترونية | D11: 320 | E11: داعمة | F11: مقدمة «لماذا كاتكس» (داخل «أفضل شركة تصميم مواقع إلكترونية»)
A12: الهب: شركة تصميم مواقع الويب | B12: المظلة | C12: تطوير مواقع / تطوير المواقع | D12: 110 | E12: داعمة | F12: مقدمة قسم الخدمات («وتطوير مواقع الويب») | G12: نعم
A13: الهب: شركة تصميم مواقع الويب | B13: المظلة | C13: شركات تصميم مواقع في القاهرة | D13: 90 | E13: داعمة | F13: فقرة المقر في «لماذا كاتكس»
A14: الهب: شركة تصميم مواقع الويب | B14: المظلة | C14: تصميم مواقع الكترونية في مصر | D14: 70 | E14: داعمة | F14: فقرة المقر في «لماذا كاتكس»
A15: الهب: شركة تصميم مواقع الويب | B15: المظلة | C15: شركة انشاء مواقع الكترونية | D15: 40 | E15: داعمة | F15: فقرة المقر في «لماذا كاتكس»
A16: الهب: شركة تصميم مواقع الويب | B16: المظلة | C16: أفضل شركة تصميم مواقع الكترونية | D16: 30 | E16: داعمة | F16: مقدمة «لماذا كاتكس»
A17: الهب: شركة تصميم مواقع الويب | B17: المظلة | C17: تطوير مواقع الويب | D17: 30 | E17: داعمة | F17: مقدمة قسم الخدمات | G17: نعم
A18: الهب: شركة تصميم مواقع الويب | B18: المظلة | C18: خدمات تصميم المواقع | D18: 20 | E18: داعمة | F18: العنوان الصغير فوق «أي خدمة تحتاج؟»
A19: الهب: شركة تصميم مواقع الويب | B19: المظلة | C19: أفضل شركة تصميم مواقع فى مصر | D19: 320 | E19: متغير | F19: —
A20: الهب: شركة تصميم مواقع الويب | B20: المظلة | C20: تصميم مواقع الكترونية | D20: 320 | E20: متغير | F20: — | G20: نعم
A21: الهب: شركة تصميم مواقع الويب | B21: المظلة | C21: أفضل شركة تصميم مواقع / افضل شركة تصميم المواقع / افضل شركة لتصميم المواقع | D21: 260 | E21: متغير | F21: داخل H2 «لماذا كاتكس»
A22: الهب: شركة تصميم مواقع الويب | B22: المظلة | C22: شركات تصميم مواقع فى مصر | D22: 260 | E22: متغير | F22: —
A23: الهب: شركة تصميم مواقع الويب | B23: المظلة | C23: شركات تصميم مواقع الكترونية في مصر | D23: 90 | E23: متغير | F23: —
A24: الهب: شركة تصميم مواقع الويب | B24: المظلة | C24: شركة تصميم مواقع الكترونية في مصر | D24: 90 | E24: متغير | F24: —
A25: الهب: شركة تصميم مواقع الويب | B25: المظلة | C25: شركات انشاء مواقع الكترونية | D25: 40 | E25: متغير | F25: —
A26: الهب: شركة تصميم مواقع الويب | B26: المظلة | C26: أفضل شركة تصميم مواقع إلكترونية | D26: 20 | E26: متغير | F26: —
A27: الهب: شركة تصميم مواقع الويب | B27: المظلة | C27: شركات تصميم مواقع الكترونية / شركات تصميم المواقع الالكترونية | D27: 20 | E27: متغير | F27: —
A28: الهب: شركة تصميم مواقع الويب | B28: المظلة | C28: شركة تصميم ويب سايت | D28: 20 | E28: متغير | F28: —
A29: الهب: شركة تصميم مواقع الويب | B29: المظلة | C29: تصميم مواقع احترافية | D29: 20 | E29: متغير | F29: — | G29: نعم

Sheet Pillar 1 - مخصص
A1: الصفحة | B1: المستوى | C1: الكلمة | D1: SV | E1: الدور | F1: الموضع في الصفحة | G1: تغيّر
A2: موقع مخصص | B2: Pillar 1 | C2: تصميم موقع إلكتروني | D2: 1600 | E2: رئيسية | F2: Title + H1 + أول جملة
A3: موقع مخصص | B3: Pillar 1 | C3: شركة برمجة مواقع | D3: 140 | E3: داعمة | F3: H2 الموقع بنظام خاص
A4: موقع مخصص | B4: Pillar 1 | C4: تصميم ويب سايت | D4: 90 | E4: داعمة | F4: نص المقدمة
A5: موقع مخصص | B5: Pillar 1 | C5: سعر تصميم موقع الكتروني | D5: 90 | E5: داعمة | F5: Meta + بطاقة السعر
A6: موقع مخصص | B6: Pillar 1 | C6: شركة برمجة وتصميم مواقع | D6: 70 | E6: داعمة | F6: نص الموقع بنظام خاص
A7: موقع مخصص | B7: Pillar 1 | C7: تصميم صفحات الويب | D7: 50 | E7: داعمة | F7: نص قسم «ما يشمله»
A8: موقع مخصص | B8: Pillar 1 | C8: تصميم مواقع شركات | D8: 50 | E8: داعمة | F8: نص الموقع الثابت
A9: موقع مخصص | B9: Pillar 1 | C9: شركة تصميم موقع الكتروني | D9: 50 | E9: داعمة | F9: نص «لماذا كاتكس» في الخدمة 1
A10: موقع مخصص | B10: Pillar 1 | C10: عرض سعر تصميم موقع الكتروني | D10: 50 | E10: داعمة | F10: زر «اطلب عرض سعر»
A11: موقع مخصص | B11: Pillar 1 | C11: تصميم صفحة هبوط | D11: 40 | E11: داعمة | F11: H3 صفحات الهبوط
A12: موقع مخصص | B12: Pillar 1 | C12: تصميم موقع إلكتروني احترافي | D12: 40 | E12: داعمة | F12: Meta
A13: موقع مخصص | B13: Pillar 1 | C13: تصميم منصة تعليمية | D13: 30 | E13: داعمة | F13: H3 أمثلة
... A27: موقع مخصص | B27: Pillar 1 | C27: موقع تعريفي لشركة | D27: 10 | E27: متغير | F27: —
A28: مقال: تكلفة إنشاء موقع إلكتروني في مصر 2026: دليل الأسعار | B28: Cluster | C28: تكلفة انشاء موقع الكتروني | D28: 140 | E28: رئيسية | F28: Title + H1 | G28: نعم
A29: مقال: تكلفة إنشاء موقع إلكتروني في مصر 2026: دليل الأسعار | B29: Cluster | C29: تكلفة تصميم موقع الكتروني | D29: 90 | E29: داعمة | F29: H2 | G29: نعم
A30: مقال: تكلفة إنشاء موقع إلكتروني في مصر 2026: دليل الأسعار | B30: Cluster | C30: تكلفة تصميم موقع الكتروني في مصر | D30: 70 | E30: داعمة | F30: H2 «في مصر» | G30: نعم
A31: مقال: تكلفة إنشاء موقع إلكتروني في مصر 2026: دليل الأسعار | B31: Cluster | C31: أسعار تصميم المواقع | D31: 50 | E31: داعمة | F31: H2 | G31: نعم
A32: مقال: تكلفة إنشاء موقع إلكتروني في مصر 2026: دليل الأسعار | B32: Cluster | C32: اسعار المواقع الالكترونية | D32: 40 | E32: داعمة | F32: H2 | G32: نعم
A33: مقال: تكلفة إنشاء موقع إلكتروني في مصر 2026: دليل الأسعار | B33: Cluster | C33: اسعار تصميم المواقع الالكترونية | D33: 40 | E33: داعمة | F33: H2 | G33: نعم
A34: مقال: تكلفة إنشاء موقع إلكتروني في مصر 2026: دليل الأسعار | B34: Cluster | C34: اسعار الويب سايت فى مصر | D34: 20 | E34: داعمة | F34: H2 | G34: نعم
A35: مقال: تكلفة إنشاء موقع إلكتروني في مصر 2026: دليل الأسعار | B35: Cluster | C35: تكلفة إنشاء موقع الكتروني | D35: 90 | E35: متغير | F35: — | G35: نعم
A36: مقال: تكلفة إنشاء موقع إلكتروني في مصر 2026: دليل الأسعار | B36: Cluster | C36: تكلفة عمل موقع الكتروني | D36: 50 | E36: متغير | F36: — | G36: نعم
A37: مقال: تكلفة إنشاء موقع إلكتروني في مصر 2026: دليل الأسعار | B37: Cluster | C37: اسعار تصميم مواقع | D37: 50 | E37: متغير | F37: — | G37: نعم
A38: مقال: تكلفة إنشاء موقع إلكتروني في مصر 2026: دليل الأسعار | B38: Cluster | C38: اسعار انشاء موقع الكتروني | D38: 30 | E38: متغير | F38: — | G38: نعم
A39: مقال: تكلفة إنشاء موقع إلكتروني في مصر 2026: دليل الأسعار | B39: Cluster | C39: كم تكلفة انشاء موقع الكتروني | D39: 10 | E39: متغير | F39: — | G39: نعم
A40: مقال: أنواع المواقع الإلكترونية | B40: Cluster | C40: انواع المواقع الالكترونية | D40: 30 | E40: رئيسية | F40: Title + H1
A41: مقال: أنواع المواقع الإلكترونية | B41: Cluster | C41: الفرق بين المتجر الالكتروني والموقع الالكتروني | D41: 20 | E41: داعمة | F41: H2
A42: مقال: أنواع المواقع الإلكترونية | B42: Cluster | C42: موقع الكتروني / الموقع الإلكتروني | D42: 8100 | E42: طبيعي فقط | F42: النص (عام جداً)
A43: مقال: أنواع المواقع الإلكترونية | B43: Cluster | C43: ويب سايت | D43: 4400 | E43: طبيعي فقط | F43: النص (عام جداً)
A44: مقال: أنواع المواقع الإلكترونية | B44: Cluster | C44: موقع ويب / مواقع الويب / موقع الويب | D44: 2900 | E44: طبيعي فقط | F44: النص (عام جداً)
A45: مقال: أنواع المواقع الإلكترونية | B45: Cluster | C45: مواقع ويب / موقع الويب | D45: 1600 | E45: طبيعي فقط | F45: النص (عام جداً)
A46: مقال: أنواع المواقع الإلكترونية | B46: Cluster | C46: موقع الإنترنت | D46: 1600 | E46: طبيعي فقط | F46: النص (عام جداً)
A47: مقال: أنواع المواقع الإلكترونية | B47: Cluster | C47: المواقع الإلكترونية / مواقع إلكترونية | D47: 390 | E47: طبيعي فقط | F47: النص
A48: مقال: أنواع المواقع الإلكترونية | B48: Cluster | C48: موقع الانترنت | D48: 210 | E48: طبيعي فقط | F48: —
A49: مقال: أنواع المواقع الإلكترونية | B49: Cluster | C49: موقع على الإنترنت | D49: 90 | E49: طبيعي فقط | F49: —
A50: مقال: أنواع المواقع الإلكترونية | B50: Cluster | C50: انواع الموقع | D50: 20 | E50: متغير | F50: —
A51: مقال: أنواع المواقع الإلكترونية | B51: Cluster | C51: انواع الويب | D51: 20 | E51: متغير | F51: —
... A62: مقال: كيف تنشئ موقعاً إلكترونياً لنشاطك: بنفسك أم مع شركة؟ | B62: Cluster | C62: انشاء موقع الويب / انشاء موقع ويب | D62: 170 | E62: داعمة | F62: H2
A63: مقال: كيف تنشئ موقعاً إلكترونياً لنشاطك: بنفسك أم مع شركة؟ | B63: Cluster | C63: انشاء صفحات ويب | D63: 50 | E63: داعمة | F63: H2 | G63: نعم
...

Sheet Pillar 2 - ووردبريس
A1: الصفحة | B1: المستوى | C1: الكلمة | D1: SV | E1: الدور | F1: الموضع في الصفحة | G1: تغيّر
A2: موقع تديره بنفسك (ووردبريس) | B2: Pillar 2 | C2: تصميم مواقع ووردبريس | D2: 140 | E2: رئيسية | F2: Title + H1 + أول جملة
A3: موقع تديره بنفسك (ووردبريس) | B3: Pillar 2 | C3: مواقع ووردبريس | D3: 170 | E3: داعمة | F3: H2
A4: موقع تديره بنفسك (ووردبريس) | B4: Pillar 2 | C4: متاجر ووردبريس | D4: 90 | E4: داعمة | F4: H3 باقة «متجر ووردبريس»
A5: موقع تديره بنفسك (ووردبريس) | B5: Pillar 2 | C5: سعر تصميم موقع ووردبريس | D5: 70 | E5: داعمة | F5: H2 السعر
A6: موقع تديره بنفسك (ووردبريس) | B6: Pillar 2 | C6: تصميم موقع اخباري | D6: 40 | E6: داعمة | F6: H3 أمثلة
A7: موقع تديره بنفسك (ووردبريس) | B7: Pillar 2 | C7: تصميم موقع ووردبريس احترافي | D7: 30 | E7: داعمة | F7: Meta
A8: موقع تديره بنفسك (ووردبريس) | B8: Pillar 2 | C8: انشاء موقع ووردبريس | D8: 20 | E8: داعمة | F8: H3 خطوات العمل
A9: موقع تديره بنفسك (ووردبريس) | B9: Pillar 2 | C9: مصمم ووردبريس | D9: 20 | E9: داعمة | F9: نص «من ينفذ موقعك»
A10: موقع تديره بنفسك (ووردبريس) | B10: Pillar 2 | C10: موقع ووردبريس | D10: 170 | E10: متغير | F10: —
A11: موقع تديره بنفسك (ووردبريس) | B11: Pillar 2 | C11: تصميم موقع ووردبريس | D11: 140 | E11: متغير | F11: —
A12: موقع تديره بنفسك (ووردبريس) | B12: Pillar 2 | C12: متجر ووردبريس | D12: 90 | E12: متغير | F12: —
A13: موقع تديره بنفسك (ووردبريس) | B13: Pillar 2 | C13: انشاء موقع على الووردبريس | D13: 10 | E13: متغير | F13: —
A14: مقال: ما هو ووردبريس، وهل يناسب موقع شركتك؟ | B14: Cluster | C14: موقع wordpress | D14: 50 | E14: رئيسية | F14: Title + H1 | G14: نعم
A15: مقال: ما هو ووردبريس، وهل يناسب موقع شركتك؟ | B15: Cluster | C15: ووردبريس عربي | D15: 90 | E15: داعمة | F15: H2 «ووردبريس بالعربي» | G15: نعم
A16: مقال: ما هو ووردبريس، وهل يناسب موقع شركتك؟ | B16: Cluster | C16: ووردبريس بالعربية | D16: 70 | E16: متغير | F16: — | G16: نعم
A17: مقال: ما هو ووردبريس، وهل يناسب موقع شركتك؟ | B17: Cluster | C17: wordpress موقع | D17: 20 | E17: متغير | F17: — | G17: نعم

Sheet Pillar 3 - المتجر
A1: الصفحة | B1: المستوى | C1: الكلمة | D1: SV | E1: الدور | F1: الموضع في الصفحة | G1: تغيّر
A2: المتجر الإلكتروني المخصص | B2: Pillar 3 | C2: تصميم متجر الكتروني | D2: 210 | E2: رئيسية | F2: Title + H1 + أول جملة
A3: المتجر الإلكتروني المخصص | B3: Pillar 3 | C3: تصميم متاجر الكترونية | D3: 170 | E3: داعمة | F3: H2
A4: المتجر الإلكتروني المخصص | B4: Pillar 3 | C4: تصميم متجر الكتروني احترافي | D4: 70 | E4: داعمة | F4: Meta
A5: المتجر الإلكتروني المخصص | B5: Pillar 3 | C5: شركات تصميم متاجر الكترونية | D5: 50 | E5: داعمة | F5: H2 «لماذا كاتكس»
A6: المتجر الإلكتروني المخصص | B6: Pillar 3 | C6: شركات تصميم متاجر الكترونية في مصر | D6: 40 | E6: داعمة | F6: فقرة الـ GEO
A7: المتجر الإلكتروني المخصص | B7: Pillar 3 | C7: إنشاء متجر شوبيفاي | D7: 30 | E7: داعمة | F7: سؤال شائع [تأكيد: هل تقدمون شوبيفاي؟]
A8: المتجر الإلكتروني المخصص | B8: Pillar 3 | C8: انشاء متجر الكتروني في مصر | D8: 30 | E8: داعمة | F8: فقرة الـ GEO
A9: المتجر الإلكتروني المخصص | B9: Pillar 3 | C9: تصميم موقع الكتروني لبيع المنتجات | D9: 30 | E9: داعمة | F9: نص المقدمة
A10: المتجر الإلكتروني المخصص | B10: Pillar 3 | C10: أفضل شركة تصميم متجر الكتروني | D10: 20 | E10: داعمة | F10: نص «لماذا كاتكس»
A11: المتجر الإلكتروني المخصص | B11: Pillar 3 | C11: تصميم واجهة متجر الكتروني | D11: 20 | E11: داعمة | F11: H3 ما يشمله
A12: المتجر الإلكتروني المخصص | B12: Pillar 3 | C12: متاجر الكترونية | D12: 1300 | E12: طبيعي فقط | F12: النص
A13: المتجر الإلكتروني المخصص | B13: Pillar 3 | C13: المتجر الالكتروني | D13: 880 | E13: طبيعي فقط | F13: النص
... A23: المتجر الإلكتروني المخصص | B23: Pillar 3 | C23: شركة تصميم متاجر الكترونية | D23: 50 | E23: متغير | F23: —
A24: مقال: تكلفة إنشاء متجر إلكتروني في مصر | B24: Cluster | C24: تكلفة عمل متجر الكتروني | D24: 260 | E24: رئيسية | F24: Title + H1 | G24: نعم
A25: مقال: تكلفة إنشاء متجر إلكتروني في مصر | B25: Cluster | C25: تكلفة انشاء متجر الكتروني | D25: 140 | E25: داعمة | F25: H2 | G25: نعم
A26: مقال: تكلفة إنشاء متجر إلكتروني في مصر | B26: Cluster | C26: تكلفة انشاء متجر الكتروني في مصر | D26: 30 | E26: داعمة | F26: H2 «في مصر» | G26: نعم
A27: مقال: تكلفة إنشاء متجر إلكتروني في مصر | B27: Cluster | C27: تكاليف انشاء متجر الكتروني | D27: 140 | E27: متغير | F27: — | G27: نعم
A28: مقال: كيف تنشئ متجراً إلكترونياً: منصة جاهزة أم متجر مخصص؟ | B28: Cluster | C28: إنشاء متجر إلكتروني | D28: 1900 | E28: رئيسية | F28: Title + H1
A29: مقال: كيف تنشئ متجراً إلكترونياً: منصة جاهزة أم متجر مخصص؟ | B29: Cluster | C29: إنشاء متجر | D29: 320 | E29: داعمة | F29: H2
A30: مقال: كيف تنشئ متجراً إلكترونياً: منصة جاهزة أم متجر مخصص؟ | B30: Cluster | C30: إنشاء موقع إلكتروني تجاري | D30: 90 | E30: داعمة | F30: H2 «إنشاء موقع تجاري لبيع منتجاتك» | G30: نعم
A31: مقال: كيف تنشئ متجراً إلكترونياً: منصة جاهزة أم متجر مخصص؟ | B31: Cluster | C31: إنشاء متجر سلة | D31: 30 | E31: داعمة | F31: H2 «إنشاء متجر على سلة» + رابط لصفحة سلة | G31: نعم
A32: مقال: كيف تنشئ متجراً إلكترونياً: منصة جاهزة أم متجر مخصص؟ | B32: Cluster | C32: عمل متجر الكتروني | D32: 70 | E32: متغير | F32: —
A33: مقال: كيف تنشئ متجراً إلكترونياً: منصة جاهزة أم متجر مخصص؟ | B33: Cluster | C33: انشاء متاجر الكترونية | D33: 30 | E33: متغير | F33: —
A34: مقال: ابدأ التجارة الإلكترونية في مصر | B34: Cluster | C34: التجارة الإلكترونية | D34: 1600 | E34: رئيسية | F34: Title + H1
A35: مقال: أفضل موقع لإنشاء متجر إلكتروني | B35: Cluster | C35: أفضل موقع لإنشاء متجر الكتروني | D35: 170 | E35: رئيسية | F35: Title + H1
A36: مقال: أفضل موقع لإنشاء متجر إلكتروني | B36: Cluster | C36: أفضل متجر إلكتروني | D36: 20 | E36: متغير | F36: —

Sheet Pillar 4 - سلة
A1: الصفحة | B1: المستوى | C1: الكلمة | D1: SV | E1: الدور | F1: الموضع في الصفحة | G1: تغيّر
A2: متجر سلة | B2: Pillar 4 | C2: تصميم متجر سلة | D2: 70 | E2: رئيسية | F2: Title + H1 + أول جملة
A3: متجر سلة | B3: Pillar 4 | C3: تصميم متاجر سلة | D3: 70 | E3: داعمة | F3: H2

Sheet الرئيسية
A1: الصفحة | B1: المستوى | C1: الكلمة | D1: SV | E1: الدور | F1: الموضع في الصفحة | G1: تغيّر
A2: الصفحة الرئيسية (قسم المواقع) | B2: الرئيسية | C2: موقعك الإلكتروني | D2: 8100 | E2: داعمة | F2: H2 قسم المواقع
A3: الصفحة الرئيسية (قسم المواقع) | B3: الرئيسية | C3: متجرك الإلكتروني | D3: 110 | E3: داعمة | F3: نص بطاقة المتاجر
A4: الصفحة الرئيسية (قسم المواقع) | B4: الرئيسية | C4: خدمات المواقع | D4: 50 | E4: داعمة | F4: العنوان الصغير فوق H2 القسم
A5: الصفحة الرئيسية (قسم المواقع) | B5: الرئيسية | C5: تصميم مواقع وتطبيقات | D5: 30 | E5: داعمة | F5: سطر الربط بقسم التطبيقات

Sheet خارج التوزيع
A1: الصفحة | B1: المستوى | C1: الكلمة | D1: SV | E1: الدور | F1: الموضع في الصفحة | G1: تغيّر
A2: غير مستهدف (نية تعلم أو وظائف) | B2: غير مستهدف | C2: تصميم مواقع الويب / تصميم مواقع ويب | D2: 4400 | E2: غير مستهدف | F2: مضمّنة داخل H1 «شركة تصميم مواقع الويب»، ولا تُستهدف بعنوان مستقل لأن نتائجها تعليمية
A3: غير مستهدف (نية تعلم أو وظائف) | B3: غير مستهدف | C3: موقع احترافي | D3: 390 | E3: غير مستهدف | F3: —
A4: غير مستهدف (نية تعلم أو وظائف) | B4: غير مستهدف | C4: موقع احترافى | D4: 320 | E4: غير مستهدف | F4: —
A5: غير مستهدف (نية تعلم أو وظائف) | B5: غير مستهدف | C5: تطوير الويب | D5: 320 | E5: غير مستهدف | F5: نية تعلم (دورات وأدلة)، لا نية شراء
A6: غير مستهدف (نية تعلم أو وظائف) | B6: غير مستهدف | C6: تصميم مواقع انترنت | D6: 110 | E6: غير مستهدف | F6: —
A7: غير مستهدف (نية تعلم أو وظائف) | B7: غير مستهدف | C7: تطوير الموقع | D7: 30 | E7: غير مستهدف | F7: —
A8: غير مستهدف (نية تعلم أو وظائف) | B8: غير مستهدف | C8: تطوير موقع ويب | D8: 30 | E8: غير مستهدف | F8: —
A9: مستبعد | B9: مستبعد | C9: متاجر سعودية الكترونية | D9: 1300 | E9: مستبعد | F9: نية تسوق أو شراء بيانات متاجر، لا بناء متجر
A10: مستبعد | B10: مستبعد | C10: شركة تصميم مواقع في الرياض | D10: 720 | E10: مستبعد | F10: لا فرع ولا عنوان في السعودية
A11: مستبعد | B11: مستبعد | C11: شركة تصميم مواقع في السعودية | D11: 390 | E11: مستبعد | F11: لا فرع ولا عنوان في السعودية
A12: مستبعد | B12: مستبعد | C12: متاجر الكترونية سعودية | D12: 210 | E12: مستبعد | F12: نية تسوق أو شراء بيانات متاجر، لا بناء متجر
A13: مستبعد | B13: مستبعد | C13: مواقع الشركات | D13: 170 | E13: مستبعد | F13: — | G13: نعم
A14: مستبعد | B14: مستبعد | C14: أفضل شركة تصميم مواقع في السعودية / افضل شركات تصميم المواقع في السعودية / افضل شركة تصميم مواقع في السعودية | D14: 170 | E14: مستبعد | F14: لا فرع ولا عنوان في السعودية
A15: مستبعد | B15: مستبعد | C15: مواقع انشاء تطبيقات | D15: 90 | E15: مستبعد | F15: نية الباحث: أدوات بناء تطبيقات ذاتية
A16: مستبعد | B16: مستبعد | C16: افضل شركة تصميم مواقع في الرياض | D16: 50 | E16: مستبعد | F16: لا فرع ولا عنوان في السعودية
A17: مستبعد | B17: مستبعد | C17: شركة تصميم مواقع الكترونية في السعودية | D17: 50 | E17: مستبعد | F17: لا فرع ولا عنوان في السعودية
A18: مستبعد | B18: مستبعد | C18: شركة تصميم مواقع بالرياض | D18: 50 | E18: مستبعد | F18: لا فرع ولا عنوان في السعودية
A19: مستبعد | B19: مستبعد | C19: اسعار تصميم المواقع في السعودية | D19: 30 | E19: مستبعد | F19: لا فرع ولا عنوان في السعودية
A20: مستبعد | B20: مستبعد | C20: ادارة المتجر الالكتروني | D20: 20 | E20: مستبعد | F20: — | G20: نعم
A21: مستبعد | B21: مستبعد | C21: ادارة المتاجر الالكترونية | D21: 20 | E21: مستبعد | F21: — | G21: نعم
A22: مستبعد | B22: مستبعد | C22: عروض تصميم مواقع | D22: 10 | E22: مستبعد | F22: — | G22: نعم
A23: مستبعد | B23: مستبعد | C23: عروض المواقع | D23: 10 | E23: مستبعد | F23: — | G23: نعم
A24: مستبعد | B24: مستبعد | C24: عروض المواقع الالكترونية | D24: 10 | E24: مستبعد | F24: — | G24: نعم
A25: مستبعد | B25: مستبعد | C25: اسعار المواقع الالكترونية في السعودية | D25: 10 | E25: مستبعد | F25: لا فرع ولا عنوان في السعودية

Sheet سجل التغييرات
A1: الكلمة | B1: SV | C1: من | D1: إلى | E1: السبب
A2: شركة تصميم مواقع | B2: 2400 | C2: الهب: شركة تصميم مواقع الويب | D2: الهب: شركة تصميم مواقع الويب | E2: تحققك من مصر: خريطة شركات محلية (Local Pack) في القاهرة + قوائم «أفضل شركات تصميم مواقع»: تجارية محلية مؤكدة
A3: تصميم مواقع | B3: 1300 | C3: الهب: شركة تصميم مواقع الويب | D3: الهب: شركة تصميم مواقع الويب | E3: تحققك من مصر: أغلب النتائج شركات
A4: تصميم مواقع / تصميم المواقع | B4: 720 | C4: غير مستهدف (نية تعلم) | D4: الهب: شركة تصميم مواقع الويب | E4: خليط: عروض خدمات ومنتديات وأدلة، يميل للتجاري
A5: تصميم المواقع الإلكترونية / تصميم مواقع الكترونيه | B5: 390 | C5: غير مستهدف (نية تعلم) | D5: الهب: شركة تصميم مواقع الويب | E5: خليط: عروض خدمات وأداة بناء وأدلة
A6: تطوير مواقع / تطوير المواقع | B6: 110 | C6: غير مستهدف (نية تعلم) | D6: الهب: شركة تصميم مواقع الويب | E6: عروض خدمات على خمسات ومستقل (يريد من ينفذ)
A7: تطوير مواقع الويب | B7: 30 | C7: غير مستهدف (نية تعلم) | D7: الهب: شركة تصميم مواقع الويب | E7: عروض خدمات على خمسات ومستقل (يريد من ينفذ) وصفحة شركة
A8: تصميم مواقع الكترونية | B8: 320 | C8: غير مستهدف (نية تعلم) | D8: الهب: شركة تصميم مواقع الويب | E8: عروض خدمات على خمسات ومستقل (يريد من ينفذ)
A9: تصميم مواقع احترافية | B9: 20 | C9: غير مستهدف (نية تعلم) | D9: الهب: شركة تصميم مواقع الويب | E9: عروض خدمات على خمسات ومستقل (يريد من ينفذ)
A10: تكلفة انشاء موقع الكتروني | B10: 140 | C10: موقع مخصص | D10: مقال: تكلفة إنشاء موقع إلكتروني في مصر 2026: دليل الأسعار | E10: تحققك من مصر: مقالات أسعار على مدونات شركات تصميم (Geexar، مسار ويب، كيان ميديا) + GoDaddy: بحث قبل الشراء، مكانها مقال
A11: تكلفة تصميم موقع الكتروني | B11: 90 | C11: موقع مخصص | D11: مقال: تكلفة إنشاء موقع إلكتروني في مصر 2026: دليل الأسعار | E11: نفس نية «تكلفة انشاء موقع»
A12: تكلفة تصميم موقع الكتروني في مصر | B12: 70 | C12: موقع مخصص | D12: مقال: تكلفة إنشاء موقع إلكتروني في مصر 2026: دليل الأسعار | E12: نفس نية «تكلفة انشاء موقع»
A13: أسعار تصميم المواقع | B13: 50 | C13: مقال: أسعار تصميم المواقع في مصر | D13: مقال: تكلفة إنشاء موقع إلكتروني في مصر 2026: دليل الأسعار | E13: مقالات أسعار وتكاليف
... A41: عروض المواقع الالكترونية | B41: 10 | C41: مقال: أسعار تصميم المواقع في مصر | D41: مستبعد | E41: غامضة: النتائج «عروض تقديمية» لا عروض أسعار
